Workbook

Sheet README
A1: NHS + Private Pension Retirement Modeller — Product Spec (v0.1)
A3: This workbook is the working spec / calculation engine for the pension planning tool. It combines NHS legacy scheme benefits (1995/2008), the 2015 CARE scheme, and private pensions (SIPP, LISA, S&S ISA) into combined retirement income projections at different retirement ages.
A6: How to use this workbook
A7: 1. Inputs
A8: Enter your own figures (blue cells) on the 'Inputs' tab. Everything else calculates automatically.
A9: 2. Legacy Scheme (1995-2008)
A10: Static calculation of any 1995/2008 Section benefits already built up (pre-2015).
A11: 3. 2015 CARE Projection
A12: Year-by-year projection of your 2015 Scheme CARE pot from your last TRS/ABS balance to your chosen retirement ages.
A13: 4. Private Pensions Projection
A14: Year-by-year growth of SIPP, LISA and S&S ISA balances.
A15: 5. Annual Allowance Check
... A26: Since October 2023 all active members sit in the 2015 Scheme, and NHS Pensions automatically compares legacy vs. 2015 scheme benefits for your remedy-period service (1 Apr 2015 - 31 Mar 2022) at the point you claim benefits, applying whichever is higher. This means your CARE opening balance from your TRS/ABS should already reflect this. This model does NOT re-run that comparison — it takes your TRS/ABS figures as the starting point. This is a deliberate simplification worth flagging clearly to users.

Sheet Inputs
A1: Inputs
A3: PERSONAL
A4: Date of birth | B4: 30025 | C4: Used to calculate your current age and State Pension age automatically below
A5: Current age (calculated) | B5: =DATEDIF(B4,TODAY(),"y") -> 44 | C5: Calculated automatically from your date of birth — whole years
A6: Current tax year (start year) | B6: 2026 | C6: e.g. 2026 for the 2026/27 tax year
A7: State Pension Age (calculated) | B7: =IF(B4<DATE(1960,4,6),66,IF(B4<DATE(1961,3,6),67,IF(B4<DATE(1977,4,6),67,68))) -> 68 | C7: Applies the legislated bands (66 / transitional-to-67 / 67 / 68). The transitional band (born 6 Apr 1960 - 5 Mar 1961) is simplified to 67 here — check your exact date at gov.uk/state-pension-age. The rise to 68 (born on/after 6 Apr 1977) is law but could still move.
A8: Estimated full State Pension (annual) | B8: 12547.6 | C8: Defaulted to the 2026/27 full new State Pension. Get YOUR real figure from your gov.uk State Pension forecast — it's lower if you have gaps in your National Insurance record (need 35 qualifying years for the full amount, 10 minimum to get anything).
A10: NHS LEGACY SCHEME (1995 / 2008 Section) — pre-2015 service
A11: Enter these straight from your TRS/ABS 'Standard Benefits' table — no need to calculate years/final pay yourself.
A12: 1995 Section — Pension (current value from TRS) | B12: 0 | C12: From the 'Pension' row of your 1995 Section Annual Benefit Statement. Leave as 0 if not applicable
A13: 1995 Section — Lump Sum (current value from TRS) | B13: 0 | C13: From the 'Lump Sum' row of your 1995 Section statement
A14: 2008 Section — Pension (current value from TRS) | B14: 0 | C14: From the 'Pension' row of your 2008 Section Annual Benefit Statement. Leave as 0 if not applicable
A15: 2008 Section — Lump Sum (current value from TRS) | B15: 0 | C15: Usually £0.00 on the statement — the 2008 Section has no automatic lump sum
A17: LEGACY PENSION GROWTH (final salary / dynamised income link)
A18: Continuous NHS pensionable service (no 5+ year break)? | B18: Yes | C18: As long as you don't have a 5+ year gap in NHS pensionable service, your 1995/2008 legacy benefits stay 'final salary linked' and keep growing in real terms every year until you claim them (see the rate below), rather than being frozen at your TRS/ABS value. Set to 'No' to model a career break breaking this link.
A19: Assumed legacy pension REAL growth rate p.a. | B19: 0.015 | C19: For GPs, legacy benefits are uprated by 'dynamised income' — Pensions Increase (CPI) + 1.5%, with a floor of 1.5% even if CPI is nil/negative. In today's-money terms (stripping out CPI, as this whole model does), that's simply +1.5% real per year. If you're an Officer rather than a GP, your link is to current pay scales instead — which can occasionally undershoot inflation, so 1.5% may be optimistic for that case; adjust down if so.
A21: NHS 2015 SCHEME (CARE)
A22: 2015 CARE pot — most recent TRS/ABS value | B22: 18000 | C22: Should already reflect McCloud remedy correction — see README
A23: ...that TRS/ABS value is as at tax year ending | B23: 2024 | C23: TRS statements are often out of date — e.g. a statement 'Updated To 31/03/2024' means enter 2024 here. The model automatically brings your pot up to date using your current pay and the assumptions below, before projecting forward.
A24: Current annual pensionable pay | B24: 80000 | C24: Total pensionable earnings this year, all NHS posts combined
A25: Assumed REAL pay growth rate p.a. (above inflation) | B25: 0.01 | C25: This is growth ABOVE inflation, not your total pay rise. AfC awards often just track or slightly beat inflation — 0-1.5% real is a reasonable long-run planning assumption. See Assumptions tab.
A26: Assumed CARE revaluation rate p.a. (REAL, above CPI) | B26: 0.015 | C26: Scheme revalues at CPI + 1.5% — since this whole model works in today's money, use just the +1.5% real element here (not CPI + 1.5%). See Assumptions tab for why.
A27: 2015 Scheme accrual rate (1/x) | B27: 54 | C27: Standard rate is 1/54 of pensionable pay each year
A29: PRIVATE PENSIONS & SAVINGS
A30: SIPP current balance | B30: 40000
A31: SIPP annual contribution (gross, with tax relief) | B31: 6000 | C31: Find this on your provider's annual statement as 'gross contribution' or 'total contribution including tax relief'. If you pay in net (relief at source), gross = net x 1.25 (basic rate 20% relief is added automatically). If you're a higher/additional rate taxpayer, extra relief you claim via Self Assessment is a tax saving to you personally, but doesn't change this gross figure.
A32: SIPP assumed REAL growth rate p.a. (after inflation) | B32: 0.045 | C32: See Assumptions tab for the historical reasoning behind this figure — it should reflect real, above-inflation returns, net of platform/fund charges, for your actual asset mix (not 100% equities).
A33: SIPP earliest access age | B33: 57 | C33: Normal Minimum Pension Age — rising to 57 from April 2028
A34: LISA current balance | B34: 15000
A35: LISA annual contribution | B35: 4000 | C35: £4,000 annual cap; 25% government bonus added separately below. You CANNOT open a new LISA after age 39, and your last eligible contribution year is age 49 — contributions automatically stop in the projection below from age 50, even though this cell still shows your figure. LISAs are also being phased out for NEW savers from ~April 2028 — see Assumptions tab for what this does and doesn't mean for you.
A36: LISA assumed REAL growth rate p.a. (after inflation) | B36: 0.045
A37: LISA access age (no penalty) | B37: 60
A38: S&S ISA current balance | B38: 25000
A39: S&S ISA annual contribution | B39: 8000
A40: S&S ISA assumed REAL growth rate p.a. (after inflation) | B40: 0.045
A42: NHS ADDITIONAL PENSION (AP) & AVCs
A43: Additional Pension (AP) purchased — annual amount | B43: 0 | C43: Extra GUARANTEED annual NHS pension you've bought (up to ~£8,946/yr for 2026/27). Leave as 0 if you haven't bought any. This adds directly to your NHS income and is subject to the same early retirement reduction as your main 2015 Scheme pension (see ERRBO section below).
A44: NHS AVC current balance | B44: 0 | C44: In-house Additional Voluntary Contributions — an INVESTED (not guaranteed) top-up within the NHS scheme. Leave as 0 if you don't have one.
A45: NHS AVC annual contribution | B45: 0
A46: NHS AVC assumed REAL growth rate p.a. (after inflation) | B46: 0.045
...

Sheet Legacy Scheme
A1: Legacy Scheme (1995 / 2008 Section) — Static Benefits
A3: These sections stopped accruing new service from the point you moved to the 2015 Scheme (or 1 April 2015 / 31 March 2022 at the latest). Values are taken directly from your TRS/ABS 'Standard Benefits' table on the Inputs tab — no years/final-pay calculation needed.
A5: 1995 Section
A6: Annual pension (from TRS/ABS) | B6: =Inputs!$B$12 -> 0
A7: Lump sum (from TRS/ABS) | B7: =Inputs!$B$13 -> 0
A9: 2008 Section
A10: Annual pension (from TRS/ABS) | B10: =Inputs!$B$14 -> 0
A11: Lump sum (from TRS/ABS) | B11: =Inputs!$B$15 -> 0 | C11: Usually £0.00 — the 2008 Section has no automatic lump sum, but can commute pension for cash at £12:£1
A13: TOTAL LEGACY
A14: Total legacy annual pension | B14: =B6+B10 -> 0
A15: Total legacy lump sum | B15: =B7+B11 -> 0

Sheet 2015 CARE Projection
A1: 2015 CARE Scheme — Year by Year Projection
A3: Projects your CARE pot forward from your last TRS/ABS balance to age 75.
A5: Catching up an out-of-date TRS/ABS balance
A6: The model assumes a TRS/ABS is typically about a year old, and Year 0 below already accounts for that. If yours is older than that (common — many are 1-3 years behind), these rows apply extra catch-up years using your current pay as a stand-in for the missing years' pay, before the main projection starts.
A7: Catch-up step | B7: Tax Year | C7: Pot at start | D7: Extra accrual (at current pay) | E7: Pot after this step
A8: 1 | B8: =Inputs!$B$23+1 -> 2025 | C8: =Inputs!$B$22 -> 18000 | D8: =IF(1<=MAX(0,Inputs!$B$6-Inputs!$B$23-1),Inputs!$B$24/Inputs!$B$27,0) -> 1481.4815 | E8: =IF(1<=MAX(0,Inputs!$B$6-Inputs!$B$23-1),C8*(1+Inputs!$B$26)+D8,C8) -> 19751.481
A9: 2 | B9: =Inputs!$B$23+2 -> 2026 | C9: =E8 -> 19751.481 | D9: =IF(2<=MAX(0,Inputs!$B$6-Inputs!$B$23-1),Inputs!$B$24/Inputs!$B$27,0) -> 0 | E9: =IF(2<=MAX(0,Inputs!$B$6-Inputs!$B$23-1),C9*(1+Inputs!$B$26)+D9,C9) -> 19751.481
A10: 3 | B10: =Inputs!$B$23+3 -> 2027 | C10: =E9 -> 19751.481 | D10: =IF(3<=MAX(0,Inputs!$B$6-Inputs!$B$23-1),Inputs!$B$24/Inputs!$B$27,0) -> 0 | E10: =IF(3<=MAX(0,Inputs!$B$6-Inputs!$B$23-1),C10*(1+Inputs!$B$26)+D10,C10) -> 19751.481
A11: 4 | B11: =Inputs!$B$23+4 -> 2028 | C11: =E10 -> 19751.481 | D11: =IF(4<=MAX(0,Inputs!$B$6-Inputs!$B$23-1),Inputs!$B$24/Inputs!$B$27,0) -> 0 | E11: =IF(4<=MAX(0,Inputs!$B$6-Inputs!$B$23-1),C11*(1+Inputs!$B$26)+D11,C11) -> 19751.481
A12: 5 | B12: =Inputs!$B$23+5 -> 2029 | C12: =E11 -> 19751.481 | D12: =IF(5<=MAX(0,Inputs!$B$6-Inputs!$B$23-1),Inputs!$B$24/Inputs!$B$27,0) -> 0 | E12: =IF(5<=MAX(0,Inputs!$B$6-Inputs!$B$23-1),C12*(1+Inputs!$B$26)+D12,C12) -> 19751.481
A13: 6 | B13: =Inputs!$B$23+6 -> 2030 | C13: =E12 -> 19751.481 | D13: =IF(6<=MAX(0,Inputs!$B$6-Inputs!$B$23-1),Inputs!$B$24/Inputs!$B$27,0) -> 0 | E13: =IF(6<=MAX(0,Inputs!$B$6-Inputs!$B$23-1),C13*(1+Inputs!$B$26)+D13,C13) -> 19751.481
A15: If your TRS is more than 7 years out of date, extend this table or get an up-to-date statement from NHS Pensions Online before relying on these figures.
A17: Year # | B17: Tax Year | C17: Age | D17: Pensionable Pay | E17: Accrual Added | F17: Opening Pot Revalued | G17: Closing Pot | H17: PIA (approx, 16x accrual)
A18: 0 | B18: =Inputs!$B$6 -> 2026 | C18: =Inputs!$B$5 -> 44 | D18: =Inputs!$B$24 -> 80000 | E18: =D18/Inputs!$B$27 -> 1481.4815 | F18: =E13*(1+Inputs!$B$26) -> 20047.754 | G18: =F18+E18 -> 21529.235 | H18: =E18*16 -> 23703.704
A19: 1 | B19: =B18+1 -> 2027 | C19: =C18+1 -> 45 | D19: =D18*(1+Inputs!$B$25) -> 80800 | E19: =D19/Inputs!$B$27 -> 1496.2963 | F19: =G18*(1+Inputs!$B$26) -> 21852.174 | G19: =F19+E19 -> 23348.47 | H19: =E19*16 -> 23940.741
A20: 2 | B20: =B19+1 -> 2028 | C20: =C19+1 -> 46 | D20: =D19*(1+Inputs!$B$25) -> 81608 | E20: =D20/Inputs!$B$27 -> 1511.2593 | F20: =G19*(1+Inputs!$B$26) -> 23698.697 | G20: =F20+E20 -> 25209.956 | H20: =E20*16 -> 24180.148
A21: 3 | B21: =B20+1 -> 2029 | C21: =C20+1 -> 47 | D21: =D20*(1+Inputs!$B$25) -> 82424.08 | E21: =D21/Inputs!$B$27 -> 1526.3719 | F21: =G20*(1+Inputs!$B$26) -> 25588.106 | G21: =F21+E21 -> 27114.478 | H21: =E21*16 -> 24421.95
A22: 4 | B22: =B21+1 -> 2030 | C22: =C21+1 -> 48 | D22: =D21*(1+Inputs!$B$25) -> 83248.321 | E22: =D22/Inputs!$B$27 -> 1541.6356 | F22: =G21*(1+Inputs!$B$26) -> 27521.195 | G22: =F22+E22 -> 29062.83 | H22: =E22*16 -> 24666.169
A23: 5 | B23: =B22+1 -> 2031 | C23: =C22+1 -> 49 | D23: =D22*(1+Inputs!$B$25) -> 84080.804 | E23: =D23/Inputs!$B$27 -> 1557.0519 | F23: =G22*(1+Inputs!$B$26) -> 29498.773 | G23: =F23+E23 -> 31055.825 | H23: =E23*16 -> 24912.831
A24: 6 | B24: =B23+1 -> 2032 | C24: =C23+1 -> 50 | D24: =D23*(1+Inputs!$B$25) -> 84921.612 | E24: =D24/Inputs!$B$27 -> 1572.6224 | F24: =G23*(1+Inputs!$B$26) -> 31521.662 | G24: =F24+E24 -> 33094.284 | H24: =E24*16 -> 25161.959
A25: 7 | B25: =B24+1 -> 2033 | C25: =C24+1 -> 51 | D25: =D24*(1+Inputs!$B$25) -> 85770.828 | E25: =D25/Inputs!$B$27 -> 1588.3487 | F25: =G24*(1+Inputs!$B$26) -> 33590.699 | G25: =F25+E25 -> 35179.047 | H25: =E25*16 -> 25413.579
A26: 8 | B26: =B25+1 -> 2034 | C26: =C25+1 -> 52 | D26: =D25*(1+Inputs!$B$25) -> 86628.536 | E26: =D26/Inputs!$B$27 -> 1604.2322 | F26: =G25*(1+Inputs!$B$26) -> 35706.733 | G26: =F26+E26 -> 37310.965 | H26: =E26*16 -> 25667.715
A27: 9 | B27: =B26+1 -> 2035 | C27: =C26+1 -> 53 | D27: =D26*(1+Inputs!$B$25) -> 87494.822 | E27: =D27/Inputs!$B$27 -> 1620.2745 | F27: =G26*(1+Inputs!$B$26) -> 37870.63 | G27: =F27+E27 -> 39490.904 | H27: =E27*16 -> 25924.392
A28: 10 | B28: =B27+1 -> 2036 | C28: =C27+1 -> 54 | D28: =D27*(1+Inputs!$B$25) -> 88369.77 | E28: =D28/Inputs!$B$27 -> 1636.4772 | F28: =G27*(1+Inputs!$B$26) -> 40083.268 | G28: =F28+E28 -> 41719.745 | H28: =E28*16 -> 26183.636
A29: 11 | B29: =B28+1 -> 2037 | C29: =C28+1 -> 55 | D29: =D28*(1+Inputs!$B$25) -> 89253.468 | E29: =D29/Inputs!$B$27 -> 1652.842 | F29: =G28*(1+Inputs!$B$26) -> 42345.541 | G29: =F29+E29 -> 43998.383 | H29: =E29*16 -> 26445.472
A30: 12 | B30: =B29+1 -> 2038 | C30: =C29+1 -> 56 | D30: =D29*(1+Inputs!$B$25) -> 90146.002 | E30: =D30/Inputs!$B$27 -> 1669.3704 | F30: =G29*(1+Inputs!$B$26) -> 44658.359 | G30: =F30+E30 -> 46327.729 | H30: =E30*16 -> 26709.927
... A52: 34 | B52: =B51+1 -> 2060 | C52: =C51+1 -> 78 | D52: =D51*(1+Inputs!$B$25) -> 112206.16 | E52: =D52/Inputs!$B$27 -> 2077.8918 | F52: =G51*(1+Inputs!$B$26) -> 110374.91 | G52: =F52+E52 -> 112452.8 | H52: =E52*16 -> 33246.269
A54: Note: 'PIA (approx)' is a simplified illustration of the pension input amount for Annual Allowance purposes (roughly 16x the year's CARE accrual). It is not the exact HMRC method, which also factors in opening value revaluation. Treat as indicative only.

Sheet Private Pensions Projection
A1: Private Pensions & Savings — Year by Year Projection
A4: Year # | B4: Tax Year | C4: Age | D4: SIPP Balance | E4: LISA Balance (incl. bonus) | F4: S&S ISA Balance | G4: NHS AVC Balance | H4: GIA Balance (net of tax drag) | I4: Combined DC Total
A5: 0 | B5: =Inputs!$B$6 -> 2026 | C5: =Inputs!$B$5 -> 44 | D5: =Inputs!$B$30*(1+Inputs!$B$32)+Inputs!$B$31 -> 47800 | E5: =Inputs!$B$34*(1+Inputs!$B$36)+IF(C5<50,Inputs!$B$35*1.25,0) -> 20675 | F5: =Inputs!$B$38*(1+Inputs!$B$40)+Inputs!$B$39 -> 34125 | G5: =Inputs!$B$44*(1+Inputs!$B$46)+Inputs!$B$45 -> 0 | H5: =Inputs!$B$53*(1+(Inputs!$B$55-Inputs!$B$57))+Inputs!$B$54 -> 0 | I5: =D5+E5+F5+G5+H5 -> 102600
A6: 1 | B6: =B5+1 -> 2027 | C6: =C5+1 -> 45 | D6: =D5*(1+Inputs!$B$32)+Inputs!$B$31 -> 55951 | E6: =E5*(1+Inputs!$B$36)+IF(C6<50,Inputs!$B$35*1.25,0) -> 26605.375 | F6: =F5*(1+Inputs!$B$40)+Inputs!$B$39 -> 43660.625 | G6: =G5*(1+Inputs!$B$46)+Inputs!$B$45 -> 0 | H6: =H5*(1+(Inputs!$B$55-Inputs!$B$57))+Inputs!$B$54 -> 0 | I6: =D6+E6+F6+G6+H6 -> 126217
A7: 2 | B7: =B6+1 -> 2028 | C7: =C6+1 -> 46 | D7: =D6*(1+Inputs!$B$32)+Inputs!$B$31 -> 64468.795 | E7: =E6*(1+Inputs!$B$36)+IF(C7<50,Inputs!$B$35*1.25,0) -> 32802.617 | F7: =F6*(1+Inputs!$B$40)+Inputs!$B$39 -> 53625.353 | G7: =G6*(1+Inputs!$B$46)+Inputs!$B$45 -> 0 | H7: =H6*(1+(Inputs!$B$55-Inputs!$B$57))+Inputs!$B$54 -> 0 | I7: =D7+E7+F7+G7+H7 -> 150896.76
A8: 3 | B8: =B7+1 -> 2029 | C8: =C7+1 -> 47 | D8: =D7*(1+Inputs!$B$32)+Inputs!$B$31 -> 73369.891 | E8: =E7*(1+Inputs!$B$36)+IF(C8<50,Inputs!$B$35*1.25,0) -> 39278.735 | F8: =F7*(1+Inputs!$B$40)+Inputs!$B$39 -> 64038.494 | G8: =G7*(1+Inputs!$B$46)+Inputs!$B$45 -> 0 | H8: =H7*(1+(Inputs!$B$55-Inputs!$B$57))+Inputs!$B$54 -> 0 | I8: =D8+E8+F8+G8+H8 -> 176687.12
A9: 4 | B9: =B8+1 -> 2030 | C9: =C8+1 -> 48 | D9: =D8*(1+Inputs!$B$32)+Inputs!$B$31 -> 82671.536 | E9: =E8*(1+Inputs!$B$36)+IF(C9<50,Inputs!$B$35*1.25,0) -> 46046.278 | F9: =F8*(1+Inputs!$B$40)+Inputs!$B$39 -> 74920.226 | G9: =G8*(1+Inputs!$B$46)+Inputs!$B$45 -> 0 | H9: =H8*(1+(Inputs!$B$55-Inputs!$B$57))+Inputs!$B$54 -> 0 | I9: =D9+E9+F9+G9+H9 -> 203638.04
A10: 5 | B10: =B9+1 -> 2031 | C10: =C9+1 -> 49 | D10: =D9*(1+Inputs!$B$32)+Inputs!$B$31 -> 92391.755 | E10: =E9*(1+Inputs!$B$36)+IF(C10<50,Inputs!$B$35*1.25,0) -> 53118.36 | F10: =F9*(1+Inputs!$B$40)+Inputs!$B$39 -> 86291.636 | G10: =G9*(1+Inputs!$B$46)+Inputs!$B$45 -> 0 | H10: =H9*(1+(Inputs!$B$55-Inputs!$B$57))+Inputs!$B$54 -> 0 | I10: =D10+E10+F10+G10+H10 -> 231801.75
A11: 6 | B11: =B10+1 -> 2032 | C11: =C10+1 -> 50 | D11: =D10*(1+Inputs!$B$32)+Inputs!$B$31 -> 102549.38 | E11: =E10*(1+Inputs!$B$36)+IF(C11<50,Inputs!$B$35*1.25,0) -> 55508.686 | F11: =F10*(1+Inputs!$B$40)+Inputs!$B$39 -> 98174.76 | G11: =G10*(1+Inputs!$B$46)+Inputs!$B$45 -> 0 | H11: =H10*(1+(Inputs!$B$55-Inputs!$B$57))+Inputs!$B$54 -> 0 | I11: =D11+E11+F11+G11+H11 -> 256232.83
A12: 7 | B12: =B11+1 -> 2033 | C12: =C11+1 -> 51 | D12: =D11*(1+Inputs!$B$32)+Inputs!$B$31 -> 113164.11 | E12: =E11*(1+Inputs!$B$36)+IF(C12<50,Inputs!$B$35*1.25,0) -> 58006.577 | F12: =F11*(1+Inputs!$B$40)+Inputs!$B$39 -> 110592.62 | G12: =G11*(1+Inputs!$B$46)+Inputs!$B$45 -> 0 | H12: =H11*(1+(Inputs!$B$55-Inputs!$B$57))+Inputs!$B$54 -> 0 | I12: =D12+E12+F12+G12+H12 -> 281763.31
A13: 8 | B13: =B12+1 -> 2034 | C13: =C12+1 -> 52 | D13: =D12*(1+Inputs!$B$32)+Inputs!$B$31 -> 124256.49 | E13: =E12*(1+Inputs!$B$36)+IF(C13<50,Inputs!$B$35*1.25,0) -> 60616.873 | F13: =F12*(1+Inputs!$B$40)+Inputs!$B$39 -> 123569.29 | G13: =G12*(1+Inputs!$B$46)+Inputs!$B$45 -> 0 | H13: =H12*(1+(Inputs!$B$55-Inputs!$B$57))+Inputs!$B$54 -> 0 | I13: =D13+E13+F13+G13+H13 -> 308442.66
A14: 9 | B14: =B13+1 -> 2035 | C14: =C13+1 -> 53 | D14: =D13*(1+Inputs!$B$32)+Inputs!$B$31 -> 135848.03 | E14: =E13*(1+Inputs!$B$36)+IF(C14<50,Inputs!$B$35*1.25,0) -> 63344.633 | F14: =F13*(1+Inputs!$B$40)+Inputs!$B$39 -> 137129.91 | G14: =G13*(1+Inputs!$B$46)+Inputs!$B$45 -> 0 | H14: =H13*(1+(Inputs!$B$55-Inputs!$B$57))+Inputs!$B$54 -> 0 | I14: =D14+E14+F14+G14+H14 -> 336322.58
A15: 10 | B15: =B14+1 -> 2036 | C15: =C14+1 -> 54 | D15: =D14*(1+Inputs!$B$32)+Inputs!$B$31 -> 147961.19 | E15: =E14*(1+Inputs!$B$36)+IF(C15<50,Inputs!$B$35*1.25,0) -> 66195.141 | F15: =F14*(1+Inputs!$B$40)+Inputs!$B$39 -> 151300.76 | G15: =G14*(1+Inputs!$B$46)+Inputs!$B$45 -> 0 | H15: =H14*(1+(Inputs!$B$55-Inputs!$B$57))+Inputs!$B$54 -> 0 | I15: =D15+E15+F15+G15+H15 -> 365457.09
A16: 11 | B16: =B15+1 -> 2037 | C16: =C15+1 -> 55 | D16: =D15*(1+Inputs!$B$32)+Inputs!$B$31 -> 160619.45 | E16: =E15*(1+Inputs!$B$36)+IF(C16<50,Inputs!$B$35*1.25,0) -> 69173.922 | F16: =F15*(1+Inputs!$B$40)+Inputs!$B$39 -> 166109.29 | G16: =G15*(1+Inputs!$B$46)+Inputs!$B$45 -> 0 | H16: =H15*(1+(Inputs!$B$55-Inputs!$B$57))+Inputs!$B$54 -> 0 | I16: =D16+E16+F16+G16+H16 -> 395902.66
A17: 12 | B17: =B16+1 -> 2038 | C17: =C16+1 -> 56 | D17: =D16*(1+Inputs!$B$32)+Inputs!$B$31 -> 173847.32 | E17: =E16*(1+Inputs!$B$36)+IF(C17<50,Inputs!$B$35*1.25,0) -> 72286.749 | F17: =F16*(1+Inputs!$B$40)+Inputs!$B$39 -> 181584.21 | G17: =G16*(1+Inputs!$B$46)+Inputs!$B$45 -> 0 | H17: =H16*(1+(Inputs!$B$55-Inputs!$B$57))+Inputs!$B$54 -> 0 | I17: =D17+E17+F17+G17+H17 -> 427718.28
... A39: 34 | B39: =B38+1 -> 2060 | C39: =C38+1 -> 78 | D39: =D38*(1+Inputs!$B$32)+Inputs!$B$31 -> 675673.62 | E39: =E38*(1+Inputs!$B$36)+IF(C39<50,Inputs!$B$35*1.25,0) -> 190378.14 | F39: =F38*(1+Inputs!$B$40)+Inputs!$B$39 -> 768656.64 | G39: =G38*(1+Inputs!$B$46)+Inputs!$B$45 -> 0 | H39: =H38*(1+(Inputs!$B$55-Inputs!$B$57))+Inputs!$B$54 -> 0 | I39: =D39+E39+F39+G39+H39 -> 1634708.4
A41: Note: LISA contributions (and the 25% bonus) automatically stop from age 50 onwards (last eligible contribution year is age 49) — the existing balance keeps growing. SIPP/ISA/AVC balances shown continue to grow here even past access age; the Scenario Summary tab decides how much of this to draw down at each retirement age. GIA growth is shown net of the assumed tax drag from the Inputs tab.

Sheet Annual Allowance Check
A1: Annual Allowance — Approximate Check
A3: Compares each year's total pension input (NHS CARE approx PIA + private pension contributions) against your Annual Allowance — automatically tapered down if you've flagged yourself as a high earner on the Inputs tab. Simplified — does not model 3-year carry-forward. Flag years that exceed the limit for closer checking.
A5: Year # | B5: Tax Year | C5: Age | D5: Total Pension Input (approx) | E5: Your Annual Allowance | F5: Within AA?
A6: ='2015 CARE Projection'!A18 -> 0 | B6: ='2015 CARE Projection'!B18 -> 2026 | C6: ='2015 CARE Projection'!C18 -> 44 | D6: ='2015 CARE Projection'!H18+Inputs!$B$31 -> 29703.704 | E6: =IF(Inputs!$B$86="Yes",MAX(10000,Inputs!$B$85-MAX(0,(Inputs!$B$87-260000)/2)),Inputs!$B$85) -> 60000 | F6: =IF(D6<=E6,"Yes","Check - over AA") -> Yes
A7: ='2015 CARE Projection'!A19 -> 1 | B7: ='2015 CARE Projection'!B19 -> 2027 | C7: ='2015 CARE Projection'!C19 -> 45 | D7: ='2015 CARE Projection'!H19+Inputs!$B$31 -> 29940.741 | E7: =IF(Inputs!$B$86="Yes",MAX(10000,Inputs!$B$85-MAX(0,(Inputs!$B$87-260000)/2)),Inputs!$B$85) -> 60000 | F7: =IF(D7<=E7,"Yes","Check - over AA") -> Yes
A8: ='2015 CARE Projection'!A20 -> 2 | B8: ='2015 CARE Projection'!B20 -> 2028 | C8: ='2015 CARE Projection'!C20 -> 46 | D8: ='2015 CARE Projection'!H20+Inputs!$B$31 -> 30180.148 | E8: =IF(Inputs!$B$86="Yes",MAX(10000,Inputs!$B$85-MAX(0,(Inputs!$B$87-260000)/2)),Inputs!$B$85) -> 60000 | F8: =IF(D8<=E8,"Yes","Check - over AA") -> Yes
A9: ='2015 CARE Projection'!A21 -> 3 | B9: ='2015 CARE Projection'!B21 -> 2029 | C9: ='2015 CARE Projection'!C21 -> 47 | D9: ='2015 CARE Projection'!H21+Inputs!$B$31 -> 30421.95 | E9: =IF(Inputs!$B$86="Yes",MAX(10000,Inputs!$B$85-MAX(0,(Inputs!$B$87-260000)/2)),Inputs!$B$85) -> 60000 | F9: =IF(D9<=E9,"Yes","Check - over AA") -> Yes
A10: ='2015 CARE Projection'!A22 -> 4 | B10: ='2015 CARE Projection'!B22 -> 2030 | C10: ='2015 CARE Projection'!C22 -> 48 | D10: ='2015 CARE Projection'!H22+Inputs!$B$31 -> 30666.169 | E10: =IF(Inputs!$B$86="Yes",MAX(10000,Inputs!$B$85-MAX(0,(Inputs!$B$87-260000)/2)),Inputs!$B$85) -> 60000 | F10: =IF(D10<=E10,"Yes","Check - over AA") -> Yes
A11: ='2015 CARE Projection'!A23 -> 5 | B11: ='2015 CARE Projection'!B23 -> 2031 | C11: ='2015 CARE Projection'!C23 -> 49 | D11: ='2015 CARE Projection'!H23+Inputs!$B$31 -> 30912.831 | E11: =IF(Inputs!$B$86="Yes",MAX(10000,Inputs!$B$85-MAX(0,(Inputs!$B$87-260000)/2)),Inputs!$B$85) -> 60000 | F11: =IF(D11<=E11,"Yes","Check - over AA") -> Yes
A12: ='2015 CARE Projection'!A24 -> 6 | B12: ='2015 CARE Projection'!B24 -> 2032 | C12: ='2015 CARE Projection'!C24 -> 50 | D12: ='2015 CARE Projection'!H24+Inputs!$B$31 -> 31161.959 | E12: =IF(Inputs!$B$86="Yes",MAX(10000,Inputs!$B$85-MAX(0,(Inputs!$B$87-260000)/2)),Inputs!$B$85) -> 60000 | F12: =IF(D12<=E12,"Yes","Check - over AA") -> Yes
A13: ='2015 CARE Projection'!A25 -> 7 | B13: ='2015 CARE Projection'!B25 -> 2033 | C13: ='2015 CARE Projection'!C25 -> 51 | D13: ='2015 CARE Projection'!H25+Inputs!$B$31 -> 31413.579 | E13: =IF(Inputs!$B$86="Yes",MAX(10000,Inputs!$B$85-MAX(0,(Inputs!$B$87-260000)/2)),Inputs!$B$85) -> 60000 | F13: =IF(D13<=E13,"Yes","Check - over AA") -> Yes
A14: ='2015 CARE Projection'!A26 -> 8 | B14: ='2015 CARE Projection'!B26 -> 2034 | C14: ='2015 CARE Projection'!C26 -> 52 | D14: ='2015 CARE Projection'!H26+Inputs!$B$31 -> 31667.715 | E14: =IF(Inputs!$B$86="Yes",MAX(10000,Inputs!$B$85-MAX(0,(Inputs!$B$87-260000)/2)),Inputs!$B$85) -> 60000 | F14: =IF(D14<=E14,"Yes","Check - over AA") -> Yes
A15: ='2015 CARE Projection'!A27 -> 9 | B15: ='2015 CARE Projection'!B27 -> 2035 | C15: ='2015 CARE Projection'!C27 -> 53 | D15: ='2015 CARE Projection'!H27+Inputs!$B$31 -> 31924.392 | E15: =IF(Inputs!$B$86="Yes",MAX(10000,Inputs!$B$85-MAX(0,(Inputs!$B$87-260000)/2)),Inputs!$B$85) -> 60000 | F15: =IF(D15<=E15,"Yes","Check - over AA") -> Yes
A16: ='2015 CARE Projection'!A28 -> 10 | B16: ='2015 CARE Projection'!B28 -> 2036 | C16: ='2015 CARE Projection'!C28 -> 54 | D16: ='2015 CARE Projection'!H28+Inputs!$B$31 -> 32183.636 | E16: =IF(Inputs!$B$86="Yes",MAX(10000,Inputs!$B$85-MAX(0,(Inputs!$B$87-260000)/2)),Inputs!$B$85) -> 60000 | F16: =IF(D16<=E16,"Yes","Check - over AA") -> Yes
A17: ='2015 CARE Projection'!A29 -> 11 | B17: ='2015 CARE Projection'!B29 -> 2037 | C17: ='2015 CARE Projection'!C29 -> 55 | D17: ='2015 CARE Projection'!H29+Inputs!$B$31 -> 32445.472 | E17: =IF(Inputs!$B$86="Yes",MAX(10000,Inputs!$B$85-MAX(0,(Inputs!$B$87-260000)/2)),Inputs!$B$85) -> 60000 | F17: =IF(D17<=E17,"Yes","Check - over AA") -> Yes
... A40: ='2015 CARE Projection'!A52 -> 34 | B40: ='2015 CARE Projection'!B52 -> 2060 | C40: ='2015 CARE Projection'!C52 -> 78 | D40: ='2015 CARE Projection'!H52+Inputs!$B$31 -> 39246.269 | E40: =IF(Inputs!$B$86="Yes",MAX(10000,Inputs!$B$85-MAX(0,(Inputs!$B$87-260000)/2)),Inputs!$B$85) -> 60000 | F40: =IF(D40<=E40,"Yes","Check - over AA") -> Yes
A42: Note: tapering assumes 'adjusted income' is the same every year for simplicity — in reality it would vary year to year with your actual earnings and pension inputs.

Sheet Scenario Summary
A1: Scenario Summary — Combined Retirement Income
A3: Compares three retirement ages side by side. This shows PROJECTIONS based on the assumptions you entered — it does not recommend which age to choose. Speak to a regulated adviser before making retirement decisions.
B5: ="Scenario A: Age "&Inputs!$B$94 -> Scenario A: Age 57 | C5: ="Scenario B: Age "&Inputs!$B$97 -> Scenario B: Age 60 | D5: ="Scenario C: Age "&Inputs!$B$100 -> Scenario C: Age 67
A6: Bridge years before NHS pension is claimed (if any) | B6: =MAX(0,Inputs!$B$95-Inputs!$B$94) -> 0 | C6: =MAX(0,Inputs!$B$98-Inputs!$B$97) -> 8 | D6: =MAX(0,Inputs!$B$101-Inputs!$B$100) -> 0 | E6: 0 = claiming immediately (the default). Positive = you're stopping work before claiming your NHS pension.
A7: NHS 2015 Scheme + AP, before early retirement reduction (at claim age) | B7: =(IFERROR(INDEX('2015 CARE Projection'!G18:G52,MATCH(Inputs!$B$94,'2015 CARE Projection'!C18:C52,0)),"n/a"))+Inputs!$B$43 -> 48708.709 | C7: =(IFERROR(INDEX('2015 CARE Projection'!G18:G52,MATCH(Inputs!$B$97,'2015 CARE Projection'!C18:C52,0)),"n/a"))+Inputs!$B$43 -> 56170.947 | D7: =(IFERROR(INDEX('2015 CARE Projection'!G18:G52,MATCH(Inputs!$B$100,'2015 CARE Projection'!C18:C52,0)),"n/a"))+Inputs!$B$43 -> 75573.513 | E7: CARE pot stops accruing new service at your retirement age. If you defer claiming past that (retirement age before claim age), you become a DEFERRED member — NHS Pensions revalues deferred CARE at CPI only, not the active member's CPI+1.5%. Since this model works in real terms with CPI already stripped out, that means no further real growth during the gap: the pot is simply held flat (in today's money) from retirement age to claim age.
A8: — early retirement reduction (ERRBO offsets this) | B8: =MAX(0,1-MAX(0,(Inputs!$B$7-Inputs!$B$95)-Inputs!$B$49)*Inputs!$B$50) -> 0.45 | C8: =MAX(0,1-MAX(0,(Inputs!$B$7-Inputs!$B$98)-Inputs!$B$49)*Inputs!$B$50) -> 1 | D8: =MAX(0,1-MAX(0,(Inputs!$B$7-Inputs!$B$101)-Inputs!$B$49)*Inputs!$B$50) -> 0.95 | E8: % of pension retained (100% = no reduction, i.e. CLAIMING at or after your State Pension Age)
A9: NHS 2015 Scheme + AP after early retirement reduction (from claim age) | B9: =B7*B8 -> 21918.919 | C9: =C7*C8 -> 56170.947 | D9: =D7*D8 -> 71794.838
A10: NHS Legacy (1995/2008) pension (from claim age) | B10: =(IF(Inputs!$B$95>=60,'Legacy Scheme'!B6,0)+IF(Inputs!$B$95>=65,'Legacy Scheme'!B10,0))*(IF(Inputs!$B$18="Yes",(1+Inputs!$B$19)^(Inputs!$B$95-Inputs!$B$5),1)) -> 0 | C10: =(IF(Inputs!$B$98>=60,'Legacy Scheme'!B6,0)+IF(Inputs!$B$98>=65,'Legacy Scheme'!B10,0))*(IF(Inputs!$B$18="Yes",(1+Inputs!$B$19)^(Inputs!$B$98-Inputs!$B$5),1)) -> 0 | D10: =(IF(Inputs!$B$101>=60,'Legacy Scheme'!B6,0)+IF(Inputs!$B$101>=65,'Legacy Scheme'!B10,0))*(IF(Inputs!$B$18="Yes",(1+Inputs!$B$19)^(Inputs!$B$101-Inputs!$B$5),1)) -> 0 | E10: Gated by standard legacy Normal Pension Ages: 60 (1995 Section), 65 (2008 Section) — pays £0 before that age. Grows in REAL terms each year until your CLAIM age via the dynamising/final-salary-link rate on the Inputs tab (continuous service assumed unless toggled off). Simplification: taking legacy benefits EARLY (with a reduction) isn't modelled — check your TRS/ABS or NHSBSA's calculator for that.
A11: Legacy lump sum (one-off, paid at claim age) | B11: =(IF(Inputs!$B$95>=60,'Legacy Scheme'!B7,0)+IF(Inputs!$B$95>=65,'Legacy Scheme'!B11,0))*(IF(Inputs!$B$18="Yes",(1+Inputs!$B$19)^(Inputs!$B$95-Inputs!$B$5),1)) -> 0 | C11: =(IF(Inputs!$B$98>=60,'Legacy Scheme'!B7,0)+IF(Inputs!$B$98>=65,'Legacy Scheme'!B11,0))*(IF(Inputs!$B$18="Yes",(1+Inputs!$B$19)^(Inputs!$B$98-Inputs!$B$5),1)) -> 0 | D11: =(IF(Inputs!$B$101>=60,'Legacy Scheme'!B7,0)+IF(Inputs!$B$101>=65,'Legacy Scheme'!B11,0))*(IF(Inputs!$B$18="Yes",(1+Inputs!$B$19)^(Inputs!$B$101-Inputs!$B$5),1)) -> 0
A12: State Pension (only if claim age >= SPA) | B12: =IF(Inputs!$B$95>=Inputs!$B$7,Inputs!$B$8,0) -> 0 | C12: =IF(Inputs!$B$98>=Inputs!$B$7,Inputs!$B$8,0) -> 12547.6 | D12: =IF(Inputs!$B$101>=Inputs!$B$7,Inputs!$B$8,0) -> 0
A13: Private pots at retirement (SIPP+LISA+ISA+AVC+GIA) | B13: =IFERROR(INDEX('Private Pensions Projection'!I5:I39,MATCH(Inputs!$B$94,'Private Pensions Projection'!C5:C39,0)),"n/a") -> 460965.6 | C13: =IFERROR(INDEX('Private Pensions Projection'!I5:I39,MATCH(Inputs!$B$97,'Private Pensions Projection'!C5:C39,0)),"n/a") -> 569956.68 | D13: =IFERROR(INDEX('Private Pensions Projection'!I5:I39,MATCH(Inputs!$B$100,'Private Pensions Projection'!C5:C39,0)),"n/a") -> 887900.42
A14: Income DURING the bridge (before you claim, if deferring) | B14: =IF(B6>0,B13/B6,0) -> 0 | C14: =IF(C6>0,C13/C6,0) -> 71244.585 | D14: =IF(D6>0,D13/D6,0) -> 0 | E14: Only applies if you set an NHS claim age later than your retirement age above — spends your private pots evenly down to zero over the gap, since that's the whole point of deferring: living off savings while your NHS pension avoids/reduces its early penalty. Shows £0 if there's no gap to bridge.
A15: Private pot remaining once claim age is reached | B15: =IF(B6>0,0,B13) -> 460965.6 | C15: =IF(C6>0,0,C13) -> 0 | D15: =IF(D6>0,0,D13) -> 887900.42 | E15: If you bridged, this is £0 — the pot was fully used getting you to claim age. If you didn't defer, it's your full pot.
A16: — ongoing drawdown from claim age onwards (see strategy on Inputs tab) | B16: =IF(Inputs!$B$90="4% Safe Withdrawal (perpetual)",B15*0.04,IF(Inputs!$B$95>=Inputs!$B$7,B15*0.04,B15/MAX(1,Inputs!$B$7-Inputs!$B$95))) -> 18438.624 | C16: =IF(Inputs!$B$90="4% Safe Withdrawal (perpetual)",C15*0.04,IF(Inputs!$B$98>=Inputs!$B$7,C15*0.04,C15/MAX(1,Inputs!$B$7-Inputs!$B$98))) -> 0 | D16: =IF(Inputs!$B$90="4% Safe Withdrawal (perpetual)",D15*0.04,IF(Inputs!$B$101>=Inputs!$B$7,D15*0.04,D15/MAX(1,Inputs!$B$7-Inputs!$B$101))) -> 35516.017 | E16: '4% Safe Withdrawal' = illustrative perpetual rate on whatever pot remains. 'Bridge' strategy here further spends any REMAINING pot down to zero by State Pension Age — only relevant if you didn't already use it all up in the bridge-to-claim phase above.
A17: Old / frozen pensions — income from claim age | B17: =(IF(Inputs!$B$63="Defined Benefit",IF(Inputs!$B$95>=Inputs!$B$65,Inputs!$B$64,0),0)+IF(Inputs!$B$63="Defined Contribution",IF(Inputs!$B$95>=Inputs!$B$68,(Inputs!$B$66*(1+Inputs!$B$67)^(Inputs!$B$95-Inputs!$B$5))*(IF(Inputs!$B$90="4% Safe Withdrawal (perpetual)",0.04,IF(Inputs!$B$95>=Inputs!$B$7,0.04,1/MAX(1,Inputs!$B$7-Inputs!$B$95)))),0),0))+(IF(Inputs!$B$70="Defined Benefit",IF(Inputs!$B$95>=Inputs!$B$72,Inputs!$B$71,0),0)+IF(Inputs!$B$70="Defined Contribution",IF(Inputs!$B$95>=Inputs!$B$75,(Inputs!$B$73*(1+Inputs!$B$74)^(Inputs!$B$95-Inputs!$B$5))*(IF(Inputs!$B$90="4% Safe Withdrawal (perpetual)",0.04,IF(Inputs!$B$95>=Inputs!$B$7,0.04,1/MAX(1,Inputs!$B$7-Inputs!$B$95)))),0),0))+(IF(Inputs!$B$77="Defined Benefit",IF(Inputs!$B$95>=Inputs!$B$79,Inputs!$B$78,0),0)+IF(Inputs!$B$77="Defined Contribution",IF(Inputs!$B$95>=Inputs!$B$82,(Inputs!$B$80*(1+Inputs!$B$81)^(Inputs!$B$95-Inputs!$B$5))*(IF(Inputs!$B$90="4% Safe Withdrawal (perpetual)",0.04,IF(Inputs!$B$95>=Inputs!$B$7,0.04,1/MAX(1,Inputs!$B$7-Inputs!$B$95)))),0),0)) -> 0 | C17: =(IF(Inputs!$B$63="Defined Benefit",IF(Inputs!$B$98>=Inputs!$B$65,Inputs!$B$64,0),0)+IF(Inputs!$B$63="Defined Contribution",IF(Inputs!$B$98>=Inputs!$B$68,(Inputs!$B$66*(1+Inputs!$B$67)^(Inputs!$B$98-Inputs!$B$5))*(IF(Inputs!$B$90="4% Safe Withdrawal (perpetual)",0.04,IF(Inputs!$B$98>=Inputs!$B$7,0.04,1/MAX(1,Inputs!$B$7-Inputs!$B$98)))),0),0))+(IF(Inputs!$B$70="Defined Benefit",IF(Inputs!$B$98>=Inputs!$B$72,Inputs!$B$71,0),0)+IF(Inputs!$B$70="Defined Contribution",IF(Inputs!$B$98>=Inputs!$B$75,(Inputs!$B$73*(1+Inputs!$B$74)^(Inputs!$B$98-Inputs!$B$5))*(IF(Inputs!$B$90="4% Safe Withdrawal (perpetual)",0.04,IF(Inputs!$B$98>=Inputs!$B$7,0.04,1/MAX(1,Inputs!$B$7-Inputs!$B$98)))),0),0))+(IF(Inputs!$B$77="Defined Benefit",IF(Inputs!$B$98>=Inputs!$B$79,Inputs!$B$78,0),0)+IF(Inputs!$B$77="Defined Contribution",IF(Inputs!$B$98>=Inputs!$B$82,(Inputs!$B$80*(1+Inputs!$B$81)^(Inputs!$B$98-Inputs!$B$5))*(IF(Inputs!$B$90="4% Safe Withdrawal (perpetual)",0.04,IF(Inputs!$B$98>=Inputs!$B$7,0.04,1/MAX(1,Inputs!$B$7-Inputs!$B$98)))),0),0)) -> 0 | D17: =(IF(Inputs!$B$63="Defined Benefit",IF(Inputs!$B$101>=Inputs!$B$65,Inputs!$B$64,0),0)+IF(Inputs!$B$63="Defined Contribution",IF(Inputs!$B$101>=Inputs!$B$68,(Inputs!$B$66*(1+Inputs!$B$67)^(Inputs!$B$101-Inputs!$B$5))*(IF(Inputs!$B$90="4% Safe Withdrawal (perpetual)",0.04,IF(Inputs!$B$101>=Inputs!$B$7,0.04,1/MAX(1,Inputs!$B$7-Inputs!$B$101)))),0),0))+(IF(Inputs!$B$70="Defined Benefit",IF(Inputs!$B$101>=Inputs!$B$72,Inputs!$B$71,0),0)+IF(Inputs!$B$70="Defined Contribution",IF(Inputs!$B$101>=Inputs!$B$75,(Inputs!$B$73*(1+Inputs!$B$74)^(Inputs!$B$101-Inputs!$B$5))*(IF(Inputs!$B$90="4% Safe Withdrawal (perpetual)",0.04,IF(Inputs!$B$101>=Inputs!$B$7,0.04,1/MAX(1,Inputs!$B$7-Inputs!$B$101)))),0),0))+(IF(Inputs!$B$77="Defined Benefit",IF(Inputs!$B$101>=Inputs!$B$79,Inputs!$B$78,0),0)+IF(Inputs!$B$77="Defined Contribution",IF(Inputs!$B$101>=Inputs!$B$82,(Inputs!$B$80*(1+Inputs!$B$81)^(Inputs!$B$101-Inputs!$B$5))*(IF(Inputs!$B$90="4% Safe Withdrawal (perpetual)",0.04,IF(Inputs!$B$101>=Inputs!$B$7,0.04,1/MAX(1,Inputs!$B$7-Inputs!$B$101)))),0),0)) -> 0 | E17: Evaluated at claim age, not retirement age — a simplification: if an old pension's own payable age falls during your bridge gap, this model doesn't add it into the bridge income above.
A19: TOTAL ANNUAL INCOME FROM CLAIM AGE (steady state) | B19: =B9+B10+B12+B16+B17 -> 40357.543 | C19: =C9+C10+C12+C16+C17 -> 68718.547 | D19: =D9+D10+D12+D16+D17 -> 107310.85
A20: (for comparison) ANNUAL INCOME DURING THE BRIDGE, if deferring | B20: =B14 -> 0 | C20: =C14 -> 71244.585 | D20: =D14 -> 0 | E20: Shows £0 if retirement age = claim age (no deferral). This is what your income looks like BEFORE the claim-age total above kicks in.
A21: One-off tax-free lump sum available | B21: =B11 -> 0 | C21: =C11 -> 0 | D21: =D11 -> 0
A23: TOTAL ANNUAL INCOME FROM STATE PENSION AGE ONWARDS | B23: =IF(Inputs!$B$95>=Inputs!$B$7,B19,B19+Inputs!$B$8) -> 52905.143 | C23: =IF(Inputs!$B$98>=Inputs!$B$7,C19,C19+Inputs!$B$8) -> 68718.547 | D23: =IF(Inputs!$B$101>=Inputs!$B$7,D19,D19+Inputs!$B$8) -> 119858.45 | E23: The claim-age total above is a steady-state figure that never includes the State Pension if you claim your NHS pension before your State Pension Age — it treats that gap the same way forever, even after you actually turn State Pension Age. This row adds the State Pension back in for scenarios that claim early, showing your true steady income from State Pension Age onwards. If you already claim at or after State Pension Age, this is identical to the row above (State Pension is already included there).

Sheet Target Income Calculator
A1: Target Income Calculator — how much more do I need to save?
A3: This shows what the maths implies you'd need to save, GIVEN the target income and assumptions you've entered — it isn't a recommendation, and it doesn't say which account to put the extra money into. Set your target on the Inputs tab.
A5: Target retirement age | B5: =Inputs!$B$105 -> 60
A6: Target annual income (today's money) | B6: =Inputs!$B$104 -> 50000
A8: Guaranteed income at target age
A9: NHS Legacy (1995/2008), if age qualifies | B9: =(IF(Inputs!$B$105>=60,'Legacy Scheme'!B6,0)+IF(Inputs!$B$105>=65,'Legacy Scheme'!B10,0))*(IF(Inputs!$B$18="Yes",(1+Inputs!$B$19)^(Inputs!$B$105-Inputs!$B$5),1)) -> 0
A10: NHS 2015 Scheme + AP, before early retirement reduction | B10: =IFERROR(INDEX('2015 CARE Projection'!G18:G52,MATCH(Inputs!$B$105,'2015 CARE Projection'!C18:C52,0)),"n/a")+Inputs!$B$43 -> 56170.947
A11: Early retirement reduction factor applied | B11: =MAX(0,1-MAX(0,(Inputs!$B$7-Inputs!$B$105)-Inputs!$B$49)*Inputs!$B$50) -> 0.6 | E11: Assumes you claim your NHS pension AT your target age (not deferred) — see the Scenario Summary tab for modelling a deferred claim separately from your retirement age
A12: NHS 2015 Scheme + AP, after reduction | B12: =B10*B11 -> 33702.568
A13: State Pension, if age qualifies | B13: =IF(Inputs!$B$105>=Inputs!$B$7,Inputs!$B$8,0) -> 0
A14: Old/frozen pensions | B14: =(IF(Inputs!$B$63="Defined Benefit",IF(Inputs!$B$105>=Inputs!$B$65,Inputs!$B$64,0),0)+IF(Inputs!$B$63="Defined Contribution",IF(Inputs!$B$105>=Inputs!$B$68,(Inputs!$B$66*(1+Inputs!$B$67)^(Inputs!$B$105-Inputs!$B$5))*(IF(Inputs!$B$90="4% Safe Withdrawal (perpetual)",0.04,IF(Inputs!$B$105>=Inputs!$B$7,0.04,1/MAX(1,Inputs!$B$7-Inputs!$B$105)))),0),0))+(IF(Inputs!$B$70="Defined Benefit",IF(Inputs!$B$105>=Inputs!$B$72,Inputs!$B$71,0),0)+IF(Inputs!$B$70="Defined Contribution",IF(Inputs!$B$105>=Inputs!$B$75,(Inputs!$B$73*(1+Inputs!$B$74)^(Inputs!$B$105-Inputs!$B$5))*(IF(Inputs!$B$90="4% Safe Withdrawal (perpetual)",0.04,IF(Inputs!$B$105>=Inputs!$B$7,0.04,1/MAX(1,Inputs!$B$7-Inputs!$B$105)))),0),0))+(IF(Inputs!$B$77="Defined Benefit",IF(Inputs!$B$105>=Inputs!$B$79,Inputs!$B$78,0),0)+IF(Inputs!$B$77="Defined Contribution",IF(Inputs!$B$105>=Inputs!$B$82,(Inputs!$B$80*(1+Inputs!$B$81)^(Inputs!$B$105-Inputs!$B$5))*(IF(Inputs!$B$90="4% Safe Withdrawal (perpetual)",0.04,IF(Inputs!$B$105>=Inputs!$B$7,0.04,1/MAX(1,Inputs!$B$7-Inputs!$B$105)))),0),0)) -> 0
A15: TOTAL guaranteed/existing income at target age | B15: =B9+B12+B13+B14 -> 33702.568
A17: The gap, and what it means for your private pot
A18: Income gap (target minus guaranteed income) | B18: =MAX(0,Inputs!$B$104-B15) -> 16297.432
A19: Total private pot needed to cover the gap | B19: =IF(Inputs!$B$90="4% Safe Withdrawal (perpetual)",B18/0.04,IF(Inputs!$B$105>=Inputs!$B$7,B18/0.04,B18*MAX(1,Inputs!$B$7-Inputs!$B$105))) -> 407435.8 | E19: Uses whichever drawdown strategy is set on the Inputs tab (4% perpetual, or bridge-to-SPA)
A20: Private pot already projected for you at that age (SIPP+LISA+ISA+AVC+GIA) | B20: =IFERROR(INDEX('Private Pensions Projection'!I5:I39,MATCH(Inputs!$B$105,'Private Pensions Projection'!C5:C39,0)),"n/a") -> 569956.68
A21: Shortfall — extra pot needed on top of your current plan | B21: =MAX(0,B19-B20) -> 0
A22: Years left to save (now to target age) | B22: =MAX(1,Inputs!$B$105-Inputs!$B$5) -> 16
A24: How much MORE you'd need to save each year, on top of what's already in your plan
B25: Cautious | C25: Central | D25: Optimistic
A26: Assumed real growth rate on extra savings | B26: =MAX(0,Inputs!$B$106-0.015) -> 0.03 | C26: =Inputs!$B$106 -> 0.045 | D26: =Inputs!$B$106+0.015 -> 0.06
A27: Extra annual saving needed (today's money) | B27: =IF(B26=0,B21/B22,B21*B26/((1+B26)^B22-1)) -> 0 | C27: =IF(C26=0,B21/B22,B21*C26/((1+C26)^B22-1)) -> 0 | D27: =IF(D26=0,B21/B22,B21*D26/((1+D26)^B22-1)) -> 0
A29: This is extra saving ON TOP OF the SIPP/LISA/ISA/AVC/GIA contributions you've already entered on the Inputs tab — it doesn't replace them. It also doesn't suggest which account to put it in; that's a personal/tax decision worth discussing with a regulated adviser, since it depends on your tax band, existing allowances used, and how soon you might need access.

Sheet Retirement Living Standards
A1: Retirement Living Standards — Pensions UK / PLSA Benchmarks
A3: Independent annual benchmarks (Pensions UK, formerly PLSA, researched by Loughborough University) for what different retirement lifestyles cost. These are spending targets, not income recommendations — figures below are the 2026 update (published June 2026). Source: retirementlivingstandards.org.uk
A5: Standard | B5: One-person household | C5: Two-person household | E5: What it typically includes
A6: Minimum | B6: 13900 | C6: 22500 | E6: Covers all basic needs with some left over for fun — a week's UK holiday, no car, modest eating out
A7: Moderate | B7: 32700 | C7: 45400 | E7: More financial security and flexibility — an annual overseas holiday, a car, eating out a few times a month
A8: Comfortable | B8: 45400 | C8: 62700 | E8: More financial freedom — long-haul-style holidays, a newer car replaced regularly, regular treats and gifts
A10: Figures assume you own your home outright (no rent/mortgage) and exclude care costs.
A12: HOW DOES YOUR PLAN COMPARE?
A13: (Uses your household type from the Inputs tab and your Scenario Summary totals)
B15: Scenario A | C15: Scenario B | D15: Scenario C
A16: Your total projected annual income | B16: ='Scenario Summary'!B19 -> 40357.543 | C16: ='Scenario Summary'!C19 -> 68718.547 | D16: ='Scenario Summary'!D19 -> 107310.85
A17: Nearest Retirement Living Standard | B17: =IF(B16<IF(Inputs!$B$109="One-person",B6,C6),"Below Minimum",IF(B16<IF(Inputs!$B$109="One-person",B7,C7),"Minimum",IF(B16<IF(Inputs!$B$109="One-person",B8,C8),"Moderate","Comfortable"))) -> Moderate | C17: =IF(C16<IF(Inputs!$B$109="One-person",B6,C6),"Below Minimum",IF(C16<IF(Inputs!$B$109="One-person",B7,C7),"Minimum",IF(C16<IF(Inputs!$B$109="One-person",B8,C8),"Moderate","Comfortable"))) -> Comfortable | D17: =IF(D16<IF(Inputs!$B$109="One-person",B6,C6),"Below Minimum",IF(D16<IF(Inputs!$B$109="One-person",B7,C7),"Minimum",IF(D16<IF(Inputs!$B$109="One-person",B8,C8),"Moderate","Comfortable"))) -> Comfortable

Sheet Assumptions & Sources
A1: Assumptions & Sources
A3: IMPORTANT: this model works entirely in TODAY'S MONEY (real terms). Every growth/revaluation rate below is the rate ABOVE inflation, not the total nominal rate — this keeps all projected figures comparable to what things cost today, rather than mixing decades of compounding inflation into the numbers. When you see '2015 Scheme revalues at CPI + 1.5%' elsewhere, only the +1.5% belongs in this model — the CPI part is inflation, which we're deliberately stripping out throughout.
A5: Assumption | B5: Default Used | C5: Source / Note
A6: 2015 Scheme accrual rate | B6: 1/54 | C6: NHS Pension Scheme rules — standard for 2015 CARE scheme
A7: 2015 Scheme CARE revaluation (REAL) | B7: 1.5% real | C7: Scheme rule is CPI + 1.5% nominal — since this model works in today's money, we use only the +1.5% real element. Source: NHS Pension Scheme regulations
A8: Pay growth assumption (REAL) | B8: 1.0% real (illustrative) | C8: This is growth ABOVE inflation. Nominal AfC pay awards have varied 2-6%, but much of that has just matched inflation — 0-1.5% real is a reasonable long-run planning range, not a forecast
A9: Standard Annual Allowance | B9: £60,000 | C9: 2026/27 HMRC limit
A10: Tapered Annual Allowance | B10: Down to £10,000 min | C10: Applies if 'adjusted income' > £260,000: AA reduces £1 for every £2 over the threshold. Toggle on Inputs tab. Source: HMRC pension tax rules — verify each tax year
A11: Normal Minimum Pension Age (private pensions) | B11: 57 | C11: Rising from 55 to 57 from 6 April 2028 — confirm protection rules if relevant
A12: LISA contribution cut-off | B12: Last eligible year: age 49 | C12: You cannot pay into a LISA (and get the government bonus) from age 50 onwards, and cannot open a new LISA after age 39. Existing balance keeps growing. Modelled automatically in the Private Pensions Projection tab
A13: LISA — future of the product | B13: Existing LISAs unaffected; NEW LISAs unavailable from ~April 2028 | C13: Announced in the Autumn 2025 Budget: the government is replacing the Lifetime ISA with a new 'First-Time Buyer ISA' for house-purchase only (no retirement-savings option), expected around April 2028 after a consultation that opened 23 June 2026. IMPORTANT — if you already have a LISA open, none of this changes anything for you: you can keep contributing under the current rules (£4,000/yr, 25% bonus, access at 60) indefinitely, even after the new product launches. The change only affects people who don't have a LISA yet and want to open one after ~2028 — they won't be able to use it as a retirement vehicle the way this model assumes. If you're relying on this model's LISA figures and don't yet have one open, opening one now (even with a small amount) secures your access to these rules long-term. Source: HM Treasury Autumn Budget 2025 / FTB ISA consultation, June 2026
A14: LISA access age (no penalty) | B14: 60 | C14: Withdrawals before 60 (other than first home purchase) incur a 25% government withdrawal charge
A15: LISA government bonus | B15: 25% | C15: Added on contributions up to £4,000/year — confirm still in payment each year
A16: Growth rates — SIPP/LISA/ISA (REAL) | B16: 4.5% real (illustrative) | C16: Based on the UBS/Credit Suisse Global Investment Returns Yearbook 2026: world equities have returned ~5.2% real annualised since 1900, though only ~3.5% since 2000. A diversified (not 100%-equity) portfolio would typically sit below the pure-equity figure — 4.5% is a middle-of-the-road illustrative assumption, not a promise. Adjust down for a more conservative asset mix, especially closer to retirement
... A31: GIA tax drag | B31: 0.5% (Basic) / 1.0% (Higher) / 1.1% (Additional) real p.a. | C31: Illustrative estimate of the annual tax cost of holding investments outside a pension/ISA, based on 2026/27 rates: dividend allowance £500 (tax at 10.75%/35.75%/39.35% by band above that), and CGT annual exempt amount £3,000 (tax at 18% basic-band / 24% higher-band gains above that). Actual drag depends heavily on your asset mix, how much is realised vs unrealised, and use of tax-efficient strategies (Bed & ISA, loss harvesting, spreading disposals across tax years) — treat this as a starting estimate, not a precise figure. Source: gov.uk Capital Gains Tax rates, HMRC dividend tax rates 2026/27

Sheet Glossary
A1: Glossary — Pension & Savings Terms
A3: This gets complex fast — use this as a quick reference. The app version would let you tap any term inline to see its definition here.
A5: Term | B5: What it means
A6: 1995 / 2008 Section | B6: The two 'legacy' NHS pension schemes, closed to new members from 2015. Final-salary based — your pension depends on your pay near the end of membership, not your career average.
A7: 2015 Scheme (CARE) | B7: The current NHS pension scheme. 'Career Average Revalued Earnings' — you build up a slice of pension each year based on that year's pay, which then grows with inflation until retirement.
A8: McCloud Remedy | B8: A legal fix for age discrimination when the 1995/2008 schemes were closed. For service between April 2015 and March 2022, NHS Pensions automatically compares legacy vs 2015 Scheme rules and gives you whichever is higher.
A9: Normal Pension Age (NPA) | B9: The age you can take your NHS pension in full, with no reduction. 60 (1995 Section), 65 (2008 Section), or your State Pension Age (2015 Scheme).
A10: Normal Minimum Pension Age (NMPA) | B10: The earliest age you can access a PRIVATE pension (SIPP etc) without penalty. Currently 55, rising to 57 from April 2028.
A11: Additional Pension (AP) | B11: A way to buy extra GUARANTEED, inflation-linked NHS pension on top of your normal 2015 Scheme benefits, up to a yearly limit (~£8,946 for 2026/27).
A12: AVC (Additional Voluntary Contribution) | B12: An in-house, INVESTED (not guaranteed) way to top up your NHS pension savings — more like a SIPP than a guaranteed pension.
A13: ERRBO (Early Retirement Reduction Buy Out) | B13: Lets 2015 Scheme members pay extra to reduce or remove the penalty for retiring before their Normal Pension Age.
A14: Annual Allowance (AA) | B14: The most you can pay into pensions each year (across all schemes combined) before facing a tax charge. £60,000 standard limit for 2026/27.
A15: Tapered Annual Allowance | B15: A reduced Annual Allowance for high earners — tapers down to a £10,000 floor if your 'adjusted income' exceeds £260,000.
A16: Pension Input Amount (PIA) | B16: The value HMRC assigns to your pension growth in a year, for Annual Allowance purposes. For DB schemes like the NHS pension, this isn't just your contributions — it's roughly 16x the increase in your annual pension.
... A29: Dynamised income / final salary link | B29: For GPs, legacy 1995/2008 pension benefits keep growing in real terms (CPI + 1.5%, with a 1.5% floor) right up until you claim them, as long as you don't have a 5+ year break in NHS pensionable service. Officers get a similar link, but to current pay scales instead.
